<?xml version="1.0" ?>
<!-- =================================================================================== -->
<!-- |    This document was autogenerated by xacro from jacobi_robot.xacro.urdf        | -->
<!-- |    EDITING THIS FILE BY HAND IS NOT RECOMMENDED                                 | -->
<!-- =================================================================================== -->
<robot name="jacobi_robot">
  <!-- link list -->
  <link name="abb_irb6700_base_link">
    <collision name="collision">
      <geometry>
        <mesh filename="meshes/abb_irb6700_150_320/collision/base_link.obj"/>
      </geometry>
      <material name="grey">
        <color rgba="0.7 0.7 0.7 1"/>
      </material>
    </collision>
    <visual name="visual">
      <geometry>
        <mesh filename="meshes/abb_irb6700_150_320/visual/base_link.obj"/>
      </geometry>
    </visual>
  </link>
  <link name="abb_irb6700_link_1">
    <collision name="collision">
      <geometry>
        <mesh filename="meshes/abb_irb6700_150_320/collision/link_1.obj"/>
      </geometry>
      <material name="grey">
        <color rgba="0.7 0.7 0.7 1"/>
      </material>
    </collision>
    <visual name="visual">
      <geometry>
        <mesh filename="meshes/abb_irb6700_150_320/visual/link_1.obj"/>
      </geometry>
    </visual>
  </link>
  <link name="abb_irb6700_link_2">
    <collision name="collision">
      <geometry>
        <mesh filename="meshes/abb_irb6700_150_320/collision/link_2.obj"/>
      </geometry>
      <material name="grey">
        <color rgba="0.7 0.7 0.7 1"/>
      </material>
    </collision>
    <visual name="visual">
      <geometry>
        <mesh filename="meshes/abb_irb6700_150_320/visual/link_2.obj"/>
      </geometry>
    </visual>
  </link>
  <link name="abb_irb6700_link_3">
    <collision name="collision">
      <geometry>
        <mesh filename="meshes/abb_irb6700_150_320/collision/link_3.obj"/>
      </geometry>
      <material name="grey">
        <color rgba="0.7 0.7 0.7 1"/>
      </material>
    </collision>
    <visual name="visual">
      <geometry>
        <mesh filename="meshes/abb_irb6700_150_320/visual/link_3.obj"/>
      </geometry>
    </visual>
  </link>
  <link name="abb_irb6700_link_4">
    <collision name="collision">
      <geometry>
        <mesh filename="meshes/abb_irb6700_150_320/collision/link_4.obj"/>
      </geometry>
      <material name="grey">
        <color rgba="0.7 0.7 0.7 1"/>
      </material>
    </collision>
    <visual name="visual">
      <geometry>
        <mesh filename="meshes/abb_irb6700_150_320/visual/link_4.obj"/>
      </geometry>
    </visual>
  </link>
  <link name="abb_irb6700_link_5">
    <collision name="collision">
      <geometry>
        <mesh filename="meshes/abb_irb6700_150_320/collision/link_5.obj"/>
      </geometry>
      <material name="grey">
        <color rgba="0.7 0.7 0.7 1"/>
      </material>
    </collision>
    <visual name="visual">
      <geometry>
        <mesh filename="meshes/abb_irb6700_150_320/visual/link_5.obj"/>
      </geometry>
    </visual>
  </link>
  <link name="abb_irb6700_link_6">
    <collision name="collision">
      <geometry>
        <mesh filename="meshes/abb_irb6700_150_320/collision/link_6.obj"/>
      </geometry>
      <material name="grey">
        <color rgba="0.3 0.3 0.3 1"/>
      </material>
    </collision>
    <visual name="visual">
      <geometry>
        <mesh filename="meshes/abb_irb6700_150_320/visual/link_6.obj"/>
      </geometry>
    </visual>
  </link>
  <!-- end of link list -->
  <!-- joint list -->
  <joint name="abb_irb6700_joint_1" type="revolute">
    <origin rpy="0 0 0" xyz="0 0 0.780"/>
    <axis xyz="0 0 1"/>
    <parent link="abb_irb6700_base_link"/>
    <child link="abb_irb6700_link_1"/>
    <limit default="0" effort="0" lower="-2.9670597283903604" upper="2.9670597283903604" velocity="1.7453292519943295"/>
  </joint>
  <joint name="abb_irb6700_joint_2" type="revolute">
    <origin rpy="0 0 0" xyz="0.320 0 0"/>
    <axis xyz="0 1 0"/>
    <parent link="abb_irb6700_link_1"/>
    <child link="abb_irb6700_link_2"/>
    <limit default="0" effort="0" lower="-1.1344640137963142" upper="1.4835298641951802" velocity="1.5707963267948966"/>
  </joint>
  <joint name="abb_irb6700_joint_3" type="revolute">
    <origin rpy="0 0 0" xyz="0 0 1.280"/>
    <axis xyz="0 1 0"/>
    <parent link="abb_irb6700_link_2"/>
    <child link="abb_irb6700_link_3"/>
    <limit default="0" effort="0" lower="-3.141592653589793" upper="1.2217304763960306" velocity="1.5707963267948966"/>
  </joint>
  <joint name="abb_irb6700_joint_4" type="revolute">
    <origin rpy="0 0 0" xyz="0 0 0.200"/>
    <axis xyz="1 0 0"/>
    <parent link="abb_irb6700_link_3"/>
    <child link="abb_irb6700_link_4"/>
    <limit default="0" effort="0" lower="-5.235987755982989" upper="5.235987755982989" velocity="2.9670597283903604"/>
  </joint>
  <joint name="abb_irb6700_joint_5" type="revolute">
    <origin rpy="0 0 0" xyz="1.5925 0 0 "/>
    <axis xyz="0 1 0"/>
    <parent link="abb_irb6700_link_4"/>
    <child link="abb_irb6700_link_5"/>
    <limit default="0" effort="0" lower="-2.2689280275926285" upper="2.2689280275926285" velocity="2.0943951023931953"/>
  </joint>
  <joint name="abb_irb6700_joint_6" type="revolute">
    <origin rpy="0 0 0" xyz="0.200 0 0 "/>
    <axis xyz="1 0 0"/>
    <parent link="abb_irb6700_link_5"/>
    <child link="abb_irb6700_link_6"/>
    <limit default="0" effort="0" lower="-6.283185307179586" upper="6.283185307179586" velocity="3.3161255787892263"/>
  </joint>
  <!-- end of joint list -->
  <!-- ROS-Industrial 'flange' frame: attachment point for EEF models -->
  <link name="abb_irb6700_flange"/>
  <joint name="abb_irb6700_joint_6-flange" type="fixed">
    <origin rpy="0 1.5707963267948966 0" xyz="0 0 0"/>
    <parent link="abb_irb6700_link_6"/>
    <child link="abb_irb6700_flange"/>
  </joint>
  <link name="linear_axis_base_link">
    <collision name="collision">
      <geometry>
        <mesh filename="meshes/linear_axis/collision/base_link.obj"/>
      </geometry>
      <material>
        <color rgba="0.7 0.7 0.7 1.0"/>
      </material>
    </collision>
    <visual name="visual">
      <geometry>
        <mesh filename="meshes/linear_axis/visual/base_link.obj"/>
      </geometry>
    </visual>
  </link>
  <link name="linear_axis_link_1">
    <collision name="collision">
      <geometry>
        <mesh filename="meshes/linear_axis/collision/link_1.obj"/>
      </geometry>
      <material>
        <color rgba="0.7 0.7 0.7 1.0"/>
      </material>
    </collision>
    <visual name="visual">
      <geometry>
        <mesh filename="meshes/linear_axis/visual/link_1.obj"/>
      </geometry>
    </visual>
  </link>
  <!-- end of link list -->
  <!-- joint list -->
  <joint name="linear_axis_joint1" type="prismatic">
    <origin rpy="0 0 0" xyz="0 0 0"/>
    <axis xyz="1 0 0"/>
    <parent link="linear_axis_base_link"/>
    <child link="linear_axis_link_1"/>
    <limit effort="1000" lower="-0.41" upper="7.3" velocity="1.0"/>
  </joint>
  <!-- end of joint list -->
  <!-- ROS-Industrial 'flange' frame: attachment point for EEF models -->
  <link name="linear_axis_flange"/>
  <joint name="linear_axis_joint1-flange" type="fixed">
    <origin rpy="0 0 0" xyz="0.6 0.43 0.55"/>
    <parent link="linear_axis_link_1"/>
    <child link="linear_axis_flange"/>
  </joint>
  <joint name="joint_axis_to_abb" type="fixed">
    <origin rpy="0 0 0" xyz="0.0 0.0 0.0"/>
    <parent link="linear_axis_flange"/>
    <child link="abb_irb6700_base_link"/>
  </joint>
</robot>
